Workbook
Name ListaEquipos: '[1]herramientas mat transp y mano'!$A$2:$A$215
Name ListaMateriales: '[1]herramientas mat transp y mano'!$E$2:$E$149
Name ListaProfesiones: '[1]herramientas mat transp y mano'!$M$2:$M$137
Name ListaTransporte: '[1]herramientas mat transp y mano'!$I$2:$I$26

Sheet herramientas mat transp y mano
A1: EQUIPOS Y HERRAMIENTAS | B1: TARIFA | C1: TARIFA +25% | E1: MATERIALES | F1: PRECIO | G1: PRECIO +25% | I1: TRANSPORTE | J1: TARIFA | K1: Columna1 | M1: PROFESIÓN | N1: NIVEL | O1: VALOR/DÍA
A2: Acarreo por km | B2: 65000 | C2: =B2*1.25 -> 81250 | E2: Abono organico x M2 | F2: 5000 | G2: =F2*1.25 -> 6250 | I2: Acarreo por km | J2: 65000 | K2: =IF(J2="",0,J2*1.25) -> 81250 | M2: ALBAÑIL | N2: 4 | O2: =IFERROR(INDEX('tabla salarial'!$AS$4:$AS$9,MATCH(N2,'tabla salarial'!$AT$4:$AT$9,0)),0) -> 407197.8
A3: Aguja Capotera | B3: 1000 | C3: =B3*1.25 -> 1250 | E3: Abrasivo aprobado | G3: =F3*1.25 -> 0 | I3: Buseta | K3: =IF(J3="",0,J3*1.25) -> 0 | M3: ALINEADOR DE TUBERÍAS | N3: 5 | O3: =IFERROR(INDEX('tabla salarial'!$AS$4:$AS$9,MATCH(N3,'tabla salarial'!$AT$4:$AT$9,0)),0) -> 443956.94
A4: Alicate diablo | B4: 500 | C4: =B4*1.25 -> 625 | E4: Aceite 15w40 | F4: 85000 | G4: =F4*1.25 -> 106250 | I4: Buseta Acpm | J4: 600000 | K4: =IF(J4="",0,J4*1.25) -> 750000 | M4: AMBIENTAL | N4: 5 | O4: =IFERROR(INDEX('tabla salarial'!$AS$4:$AS$9,MATCH(N4,'tabla salarial'!$AT$4:$AT$9,0)),0) -> 443956.94
A5: Alicate machosolo | B5: 3000 | C5: =B5*1.25 -> 3750 | E5: Aceite 4t gal | F5: 85000 | G5: =F5*1.25 -> 106250 | I5: cama baja | K5: =IF(J5="",0,J5*1.25) -> 0 | M5: ANALISTA DE GESTIÓN DE MANTENIMIENTO | N5: 3 | O5: =IFERROR(INDEX('tabla salarial'!$AS$4:$AS$9,MATCH(N5,'tabla salarial'!$AT$4:$AT$9,0)),0) -> 371571.33
A6: Alicate universal | B6: 500 | C6: =B6*1.25 -> 625 | E6: Aceite lubricante | F6: 65000 | G6: =F6*1.25 -> 81250 | I6: camion cinterna | J6: 1500000 | K6: =IF(J6="",0,J6*1.25) -> 1875000 | M6: ANDAMIERO | N6: 4 | O6: =IFERROR(INDEX('tabla salarial'!$AS$4:$AS$9,MATCH(N6,'tabla salarial'!$AT$4:$AT$9,0)),0) -> 407197.8
A7: Almadana 3" Bronce | B7: 3000 | C7: =B7*1.25 -> 3750 | E7: Acero 60000 psi kg | F7: 6350 | G7: =F7*1.25 -> 7937.5 | I7: Camión doble cabina | J7: 550000 | K7: =IF(J7="",0,J7*1.25) -> 687500 | M7: ANDAMIERO 1 | N7: 4 | O7: =IFERROR(INDEX('tabla salarial'!$AS$4:$AS$9,MATCH(N7,'tabla salarial'!$AT$4:$AT$9,0)),0) -> 407197.8
A8: Almadana 6" Bronce | B8: 6000 | C8: =B8*1.25 -> 7500 | E8: Acero de refuerzo G-60 figurado | F8: 4341 | G8: =F8*1.25 -> 5426.25 | I8: Camion Grua | J8: 3650000 | K8: =IF(J8="",0,J8*1.25) -> 4562500 | M8: ANDAMIERO 1A | N8: 5 | O8: =IFERROR(INDEX('tabla salarial'!$AS$4:$AS$9,MATCH(N8,'tabla salarial'!$AT$4:$AT$9,0)),0) -> 443956.94
A9: Almadana en bronce | B9: 450 | C9: =B9*1.25 -> 562.5 | E9: Acpm Galon | F9: 11500 | G9: =F9*1.25 -> 14375 | I9: Camion Sisterna | J9: 1500000 | K9: =IF(J9="",0,J9*1.25) -> 1875000 | M9: APAREJADOR | N9: 3 | O9: =IFERROR(INDEX('tabla salarial'!$AS$4:$AS$9,MATCH(N9,'tabla salarial'!$AT$4:$AT$9,0)),0) -> 371571.33
A10: almadana x6 lb | B10: 20000 | C10: =B10*1.25 -> 25000 | E10: Adoquín de concreto o arcilla | F10: 2750 | G10: =F10*1.25 -> 3437.5 | I10: Concretadora Bulto y Medio Acpm | J10: 600000 | K10: =I1:K10=IF(J10="",0,J10*1.25) -> 0 | M10: APAREJADOR DE GRÚA / APAREJADOR DE CARGAS / APAREJADOR DE EQUIPOS DE IZAJE* | N10: 2 | O10: =IFERROR(INDEX('tabla salarial'!$AS$4:$AS$9,MATCH(N10,'tabla salarial'!$AT$4:$AT$9,0)),0) -> 355821.88
A11: Andamios Layher | B11: 135000 | C11: =B11*1.25 -> 168750 | E11: Adoquín tipo corbatin | F11: 2200 | G11: =F11*1.25 -> 2750 | I11: mini cargador | J11: 840000 | K11: =IF(J11="",0,J11*1.25) -> 1050000 | M11: AUXILIAR ADMINISTRATIVO | N11: 2 | O11: =IFERROR(INDEX('tabla salarial'!$AS$4:$AS$9,MATCH(N11,'tabla salarial'!$AT$4:$AT$9,0)),0) -> 355821.88
A12: Arnés de seguridad y Erlingas | B12: 9000 | C12: =B12*1.25 -> 11250 | E12: Adoquin tolete | F12: 1800 | G12: =F12*1.25 -> 2250 | I12: minicargador | J12: 840000 | K12: =IF(J12="",0,J12*1.25) -> 1050000 | M12: AUXILIAR AMBIENTAL | N12: 3 | O12: =IFERROR(INDEX('tabla salarial'!$AS$4:$AS$9,MATCH(N12,'tabla salarial'!$AT$4:$AT$9,0)),0) -> 371571.33
A13: aspiradora industrial | B13: 60000 | C13: =B13*1.25 -> 75000 | E13: Agua m3 | F13: 6000 | G13: =F13*1.25 -> 7500 | I13: moto nieveladora | J13: 1820000 | K13: =IF(J13="",0,J13*1.25) -> 2275000 | M13: AUXILIAR CIVIL | N13: 1 | O13: =IFERROR(INDEX('tabla salarial'!$AS$4:$AS$9,MATCH(N13,'tabla salarial'!$AT$4:$AT$9,0)),0) -> 382109.06
A14: Avisos de seguridad | B14: 1000 | C14: =B14*1.25 -> 1250 | E14: Alambre Galvanizado 14 - kilo | F14: 14000 | G14: =F14*1.25 -> 17500 | I14: Moto niveladora | J14: 1820000 | K14: =IF(J14="",0,J14*1.25) -> 2275000 | M14: AUXILIAR DE ASEO Y CAFETERIA | N14: 1 | O14: =IFERROR(INDEX('tabla salarial'!$AS$4:$AS$9,MATCH(N14,'tabla salarial'!$AT$4:$AT$9,0)),0) -> 382109.06
A15: Azadon | B15: 700 | C15: =B15*1.25 -> 875 | E15: Alambre HG calibre 14 | F15: 14000 | G15: =F15*1.25 -> 17500 | I15: pavimentadora | J15: 4000000 | K15: =IF(J15="",0,J15*1.25) -> 5000000 | M15: AUXILIAR DE ENFERMERÍA | N15: 3 | O15: =IFERROR(INDEX('tabla salarial'!$AS$4:$AS$9,MATCH(N15,'tabla salarial'!$AT$4:$AT$9,0)),0) -> 371571.33
A16: Balde concretero | B16: 500 | C16: =B16*1.25 -> 625 | E16: Alambre negro para amarre | F16: 7592 | G16: =F16*1.25 -> 9490 | I16: retro excavadora de llanta | J16: 1330000 | K16: =IF(J16="",0,J16*1.25) -> 1662500 | M16: AUXILIAR DE INVENTARIOS | N16: 2 | O16: =IFERROR(INDEX('tabla salarial'!$AS$4:$AS$9,MATCH(N16,'tabla salarial'!$AT$4:$AT$9,0)),0) -> 355821.88
A17: Baldes Asfalto | B17: 12000 | C17: =B17*1.25 -> 15000 | E17: ARENA DE SANDBLASTING TIPO SOGAMOSO | F17: 11934 | G17: =F17*1.25 -> 14917.5 | I17: Retroexcavadora con llantas | J17: 190000 | K17: =IF(J17="",0,J17*1.25) -> 237500 | M17: AUXILIAR DE MATERIALES | N17: 3 | O17: =IFERROR(INDEX('tabla salarial'!$AS$4:$AS$9,MATCH(N17,'tabla salarial'!$AT$4:$AT$9,0)),0) -> 371571.33
A18: Banco figuracion | B18: 3000 | C18: =B18*1.25 -> 3750 | E18: Arena fina seca para sello de juntas | F18: 21000 | G18: =F18*1.25 -> 26250 | I18: Retroexcavadora de llantas | J18: 1330000 | K18: =IF(J18="",0,J18*1.25) -> 1662500 | M18: AYUDANTE CADENERO | N18: 2 | O18: =IFERROR(INDEX('tabla salarial'!$AS$4:$AS$9,MATCH(N18,'tabla salarial'!$AT$4:$AT$9,0)),0) -> 355821.88
A19: Barra | B19: 1500 | C19: =B19*1.25 -> 1875 | E19: Arena para cama/capa de soporte | F19: 31000 | G19: =F19*1.25 -> 38750 | I19: Retroexcavadora de oruga | J19: 322000 | K19: =IF(J19="",0,J19*1.25) -> 402500 | M19: AYUDANTE DE BODEGA O BODEGUERO | N19: 2 | O19: =IFERROR(INDEX('tabla salarial'!$AS$4:$AS$9,MATCH(N19,'tabla salarial'!$AT$4:$AT$9,0)),0) -> 355821.88
A20: bichiroque | B20: 1000 | C20: =B20*1.25 -> 1250 | E20: Aspersores | F20: 34900 | G20: =F20*1.25 -> 43625 | I20: Transporte de equipo oruga | J20: 4500000 | K20: =IF(J20="",0,J20*1.25) -> 5625000 | M20: AYUDANTE DE OBRA CIVIL | N20: 2 | O20: =IFERROR(INDEX('tabla salarial'!$AS$4:$AS$9,MATCH(N20,'tabla salarial'!$AT$4:$AT$9,0)),0) -> 355821.88
A21: Bomba para concreto m3 | B21: 70000 | C21: =B21*1.25 -> 87500 | E21: Avisos de seguridad | F21: 500 | G21: =F21*1.25 -> 625 | I21: traslado de equipos | J21: 1650000 | K21: =IF(J21="",0,J21*1.25) -> 2062500 | M21: AYUDANTE DE PINTURA | N21: 2 | O21: =IFERROR(INDEX('tabla salarial'!$AS$4:$AS$9,MATCH(N21,'tabla salarial'!$AT$4:$AT$9,0)),0) -> 355821.88
A22: Bomba para fumigar | B22: 5000 | C22: =B22*1.25 -> 6250 | E22: base asfáltica o base negra m3 | F22: 390000 | G22: =F22*1.25 -> 487500 | I22: trasporte de equipo | J22: 4500000 | K22: =IF(J22="",0,J22*1.25) -> 5625000 | M22: AYUDANTE ELECTRICISTA | N22: 2 | O22: =IFERROR(INDEX('tabla salarial'!$AS$4:$AS$9,MATCH(N22,'tabla salarial'!$AT$4:$AT$9,0)),0) -> 355821.88
... A25: Buldron | B25: 5000 | C25: =B25*1.25 -> 6250 | E25: Bolsa para Basura | F25: 1500 | G25: =F25*1.25 -> 1875 | I25: volqueta 14 M3 | J25: 1250000 | K25: =IF(J25="",0,J25*1.25) -> 1562500 | M25: AYUDANTE MECANICO | N25: 4 | O25: =IFERROR(INDEX('tabla salarial'!$AS$4:$AS$9,MATCH(N25,'tabla salarial'!$AT$4:$AT$9,0)),0) -> 407197.8
A26: Burro Metalico Hechizo Diferencial | B26: 5000 | C26: =B26*1.25 -> 6250 | E26: Bordillo/sardinel/confinamiento | G26: =F26*1.25 -> 0 | I26: Volqueta de 14 m³ | J26: 1350000 | K26: =IF(J26="",0,J26*1.25) -> 1687500 | M26: AYUDANTE MECÁNICO | N26: 2 | O26: =IFERROR(INDEX('tabla salarial'!$AS$4:$AS$9,MATCH(N26,'tabla salarial'!$AT$4:$AT$9,0)),0) -> 355821.88
A27: Burro Metalico Hechizo Tubería | B27: 3000 | C27: =B27*1.25 -> 3750 | E27: Broca Rotomartillo 1 1/4 x 12" | F27: 455000 | G27: =F27*1.25 -> 568750 | M27: AYUDANTE MECÁNICO OFF SHORE | N27: 2 | O27: =IFERROR(INDEX('tabla salarial'!$AS$4:$AS$9,MATCH(N27,'tabla salarial'!$AT$4:$AT$9,0)),0) -> 355821.88
A28: Buseta acpm | B28: 600000 | C28: =B28*1.25 -> 750000 | E28: Broca tipo pala | F28: 65000 | G28: =F28*1.25 -> 81250 | M28: AYUDANTE MTTO VEHICULOS | N28: 1 | O28: =IFERROR(INDEX('tabla salarial'!$AS$4:$AS$9,MATCH(N28,'tabla salarial'!$AT$4:$AT$9,0)),0) -> 382109.06
A29: Cabo para pala | B29: 20000 | C29: =B29*1.25 -> 25000 | E29: Broca tipo punta | F29: 65000 | G29: =F29*1.25 -> 81250 | M29: AYUDANTE PAILERÍA | N29: 2 | O29: =IFERROR(INDEX('tabla salarial'!$AS$4:$AS$9,MATCH(N29,'tabla salarial'!$AT$4:$AT$9,0)),0) -> 355821.88
A30: Caja De Herramientas | B30: 10000 | C30: =B30*1.25 -> 12500 | E30: brocha 3" | F30: 20000 | G30: =F30*1.25 -> 25000 | M30: AYUDANTE SOLDADURA | N30: 2 | O30: =IFERROR(INDEX('tabla salarial'!$AS$4:$AS$9,MATCH(N30,'tabla salarial'!$AT$4:$AT$9,0)),0) -> 355821.88
A31: Camilla primeros auxilios | B31: 3000 | C31: =B31*1.25 -> 3750 | E31: Cal | F31: 50000 | G31: =F31*1.25 -> 62500 | M31: AYUDANTE SOLDADURA* | N31: 4 | O31: =IFERROR(INDEX('tabla salarial'!$AS$4:$AS$9,MATCH(N31,'tabla salarial'!$AT$4:$AT$9,0)),0) -> 407197.8
A32: Camión doble cabina | B32: 550000 | C32: =B32*1.25 -> 687500 | E32: careta de esmerilar para casco | F32: 42000 | G32: =F32*1.25 -> 52500 | M32: AYUDANTE TUBERÍA | N32: 2 | O32: =IFERROR(INDEX('tabla salarial'!$AS$4:$AS$9,MATCH(N32,'tabla salarial'!$AT$4:$AT$9,0)),0) -> 355821.88
A33: Carpa plastica 10x6 | B33: 40000 | C33: =B33*1.25 -> 50000 | E33: Carpa plastica 4x4 | F33: 27500 | G33: =F33*1.25 -> 34375 | M33: BUZO SEGUNDA | N33: 3 | O33: =IFERROR(INDEX('tabla salarial'!$AS$4:$AS$9,MATCH(N33,'tabla salarial'!$AT$4:$AT$9,0)),0) -> 371571.33
A34: Carpa plastica 4x4 | B34: 27500 | C34: =B34*1.25 -> 34375 | E34: Carpa plastica 6x4 | F34: 30000 | G34: =F34*1.25 -> 37500 | M34: CADENERO 1 | N34: 4 | O34: =IFERROR(INDEX('tabla salarial'!$AS$4:$AS$9,MATCH(N34,'tabla salarial'!$AT$4:$AT$9,0)),0) -> 407197.8
A35: Carpa plastica 6x4 | B35: 30000 | C35: =B35*1.25 -> 37500 | E35: Carpa plastica 6x6 | F35: 32500 | G35: =F35*1.25 -> 40625 | M35: CAMARERA | N35: 1 | O35: =IFERROR(INDEX('tabla salarial'!$AS$4:$AS$9,MATCH(N35,'tabla salarial'!$AT$4:$AT$9,0)),0) -> 382109.06
A36: Carpa plastica 6x6 | B36: 32500 | C36: =B36*1.25 -> 40625 | E36: Catalizador/endurecedor | G36: =F36*1.25 -> 0 | M36: CAMARERO | N36: 2 | O36: =IFERROR(INDEX('tabla salarial'!$AS$4:$AS$9,MATCH(N36,'tabla salarial'!$AT$4:$AT$9,0)),0) -> 355821.88
A37: Carretilla | B37: 1500 | C37: =B37*1.25 -> 1875 | E37: Cemento 50 kl | F37: 38000 | G37: =F37*1.25 -> 47500 | M37: CAPATAZ | N37: 6 | O37: =IFERROR(INDEX('tabla salarial'!$AS$4:$AS$9,MATCH(N37,'tabla salarial'!$AT$4:$AT$9,0)),0) -> 555393.74
A38: cepillo de alambre bronce | B38: 3000 | C38: =B38*1.25 -> 3750 | E38: Cespedon x M2 | F38: 35000 | G38: =F38*1.25 -> 43750 | M38: CAPATAZ DE ZONAS VERDES Y ROCERIA* | N38: 4 | O38: =IFERROR(INDEX('tabla salarial'!$AS$4:$AS$9,MATCH(N38,'tabla salarial'!$AT$4:$AT$9,0)),0) -> 407197.8
A39: Chaleco reflectivo | B39: 625 | C39: =B39*1.25 -> 781.25 | E39: Cespedon x M2 | F39: 43750 | G39: =F39*1.25 -> 54687.5 | M39: CONDUCTOR | N39: 2 | O39: =IFERROR(INDEX('tabla salarial'!$AS$4:$AS$9,MATCH(N39,'tabla salarial'!$AT$4:$AT$9,0)),0) -> 355821.88
A40: cincel 3/4 x 12" | B40: 3000 | C40: =B40*1.25 -> 3750 | E40: Chaleco Reflectivo | F40: 20000 | G40: =F40*1.25 -> 25000 | M40: CONDUCTOR DE VEHÍCULO LIVIANO Y/O PASAJEROS | N40: 1 | O40: =IFERROR(INDEX('tabla salarial'!$AS$4:$AS$9,MATCH(N40,'tabla salarial'!$AT$4:$AT$9,0)),0) -> 382109.06
A41: Codal Aluminio 3 m | B41: 3000 | C41: =B41*1.25 -> 3750 | E41: cinta de enmascarar 2" rollo | F41: 14900 | G41: =F41*1.25 -> 18625 | M41: CONDUCTOR VEHÍCULO PESADO PROPIO DE LA INDUSTRIA DE MÁS DE 3 TON | N41: 3 | O41: =IFERROR(INDEX('tabla salarial'!$AS$4:$AS$9,MATCH(N41,'tabla salarial'!$AT$4:$AT$9,0)),0) -> 371571.33
A42: Codo sanitaria 6" Reutilizar | B42: 10000 | C42: =B42*1.25 -> 12500 | E42: Cinta de seguridad amarilla/negra x 500 | F42: 55000 | G42: =F42*1.25 -> 68750 | M42: CONECTOR OFF SHORE | N42: 2 | O42: =IFERROR(INDEX('tabla salarial'!$AS$4:$AS$9,MATCH(N42,'tabla salarial'!$AT$4:$AT$9,0)),0) -> 355821.88
...

Sheet trazado,locali y replanteo
A1: TRAZADO, LOCALIZACIÓN Y REPLANTEO
A2: EQUIPOS | B2: CANT | C2: REND/DIA | D2: TARIFA/DIA | E2: VR.PARCIAL | F2: M2
F3: 781
A4: Machete | B4: 1 | C4: 6 | D4: =IFERROR(VLOOKUP(A4,[1]!TablaEquipos[#Data],2,FALSE),0) -> 1500 | E4: =B4*C4*D4 -> 9000
A5: Martillo | B5: 1 | C5: 6 | D5: =IFERROR(VLOOKUP(A5,[1]!TablaEquipos[#Data],2,FALSE),0) -> 700 | E5: =B5*C5*D5 -> 4200
A6: Pala | B6: 1 | C6: 6 | D6: =IFERROR(VLOOKUP(A6,[1]!TablaEquipos[#Data],2,FALSE),0) -> 700 | E6: =B6*C6*D6 -> 4200
A7: Barra | B7: 1 | C7: 6 | D7: =IFERROR(VLOOKUP(A7,[1]!TablaEquipos[#Data],2,FALSE),0) -> 1500 | E7: =B7*C7*D7 -> 9000
A8: Carretilla | B8: 1 | C8: 6 | D8: =IFERROR(VLOOKUP(A8,[1]!TablaEquipos[#Data],2,FALSE),0) -> 1500 | E8: =B8*C8*D8 -> 9000
A9: Sombrilla para sol | B9: 1 | C9: 6 | D9: =IFERROR(VLOOKUP(A9,[1]!TablaEquipos[#Data],2,FALSE),0) -> 2000 | E9: =B9*C9*D9 -> 12000
A10: Detector de tubería | B10: 1 | C10: 6 | D10: =IFERROR(VLOOKUP(A10,[1]!TablaEquipos[#Data],2,FALSE),0) -> 150000 | E10: =B10*C10*D10 -> 900000
A11: Gps | B11: 1 | C11: 6 | D11: =IFERROR(VLOOKUP(A11,[1]!TablaEquipos[#Data],2,FALSE),0) -> 100000 | E11: =B11*C11*D11 -> 600000
A12: Plomada | B12: 1 | C12: 6 | D12: =IFERROR(VLOOKUP(A12,[1]!TablaEquipos[#Data],2,FALSE),0) -> 1500 | E12: =B12*C12*D12 -> 9000
A13: Nivel 18" | B13: 1 | C13: 6 | D13: =IFERROR(VLOOKUP(A13,[1]!TablaEquipos[#Data],2,FALSE),0) -> 2000 | E13: =B13*C13*D13 -> 12000
A14: Escuadra metalica 24" | B14: 1 | C14: 6 | D14: =IFERROR(VLOOKUP(A14,[1]!TablaEquipos[#Data],2,FALSE),0) -> 1000 | E14: =B14*C14*D14 -> 6000
A15: thermo agua
F17: =SUM(E4:E16) -> 1574400
A18: MATERIALES | B18: CANT | C18: REND/DIA | D18: TARIFA | E18: VR.PARCIAL
A19: Listón de madera 2 x 4 x 3 | D19: =IFERROR(VLOOKUP(A19,[1]!TablaMateriales[#Data],2,FALSE),0) -> 35000 | E19: =B19*D19 -> 0
A20: Listón de madera 2 x 1 x 3 | B20: 50 | D20: =IFERROR(VLOOKUP(A20,[1]!TablaMateriales[#Data],2,FALSE),0) -> 20000 | E20: =B20*D20 -> 1000000
A21: Cal | D21: =IFERROR(VLOOKUP(A21,[1]!TablaMateriales[#Data],2,FALSE),0) -> 50000 | E21: =B21*D21 -> 0
A22: Nailon/hilo de alineación | B22: 2 | D22: =IFERROR(VLOOKUP(A22,[1]!TablaMateriales[#Data],2,FALSE),0) -> 25000 | E22: =B22*D22 -> 50000
A23: Puntilla de 2,5" | B23: 5 | D23: =IFERROR(VLOOKUP(A23,[1]!TablaMateriales[#Data],2,FALSE),0) -> 9500 | E23: =B23*D23 -> 47500
A24: Puntilla de 3,5" | D24: =IFERROR(VLOOKUP(A24,[1]!TablaMateriales[#Data],2,FALSE),0) -> 9500 | E24: =B24*D24 -> 0
A25: Clavo de acero de 3" | B25: 3 | D25: =IFERROR(VLOOKUP(A25,[1]!TablaMateriales[#Data],2,FALSE),0) -> 15000 | E25: =B25*D25 -> 45000
A26: Pintura en aerosol | B26: 20 | D26: =IFERROR(VLOOKUP(A26,[1]!TablaMateriales[#Data],2,FALSE),0) -> 20000 | E26: =B26*D26 -> 400000
A27: Cinta de seguridad amarilla/negra x 500 | B27: 5 | D27: =IFERROR(VLOOKUP(A27,[1]!TablaMateriales[#Data],2,FALSE),0) -> 55000 | E27: =B27*D27 -> 275000
D30: =IFERROR(VLOOKUP(A30,[1]!TablaMateriales[#Data],2,FALSE),0) -> 0
D31: =IFERROR(VLOOKUP(A31,[1]!TablaMateriales[#Data],2,FALSE),0) -> 0 | E31: =B31*D31 -> 0
F32: =SUM(E19:E31) -> 1817500
A33: MANO DE OBRA | B33: CANT | C33: REND/DIA | D33: SALARIO | E33: VR.PARCIAL
A34: Capataz | B34: 1 | C34: 3.52 | D34: ='tabla salarial'!AS4 -> 555393.74 | E34: =B34*C34*D34 -> 1954986
A35: Hse | B35: 1 | C35: 3.52 | D35: ='tabla salarial'!AS4 -> 555393.74 | E35: =B35*C35*D35 -> 1954986
A36: Oficial construccion | B36: 1 | C36: 10.5 | D36: ='tabla salarial'!AS7 -> 371571.33 | E36: =B36*C36*D36 -> 3901499
A37: Auxiliar Administrativo | B37: 1 | C37: 3.52 | D37: ='tabla salarial'!AS8 -> 355821.88 | E37: =B37*C37*D37 -> 1252493
A38: Auxiliar civil | B38: 1 | C38: 10.5 | D38: ='tabla salarial'!AS9 -> 382109.06 | E38: =B38*C38*D38 -> 4012145.1
F41: =SUM(E34:E38) -> 13076109
A42: TRANSPORTE | B42: CANT | C42: REND/DIA | D42: TARIFA | E42: VR.PARCIAL
E43: =B43*C43*D43 -> 0
A44: buseta acpm | B44: 1 | C44: 2 | D44: 550000 | E44: =B44*C44*D44 -> 1100000
D45: =IFERROR(VLOOKUP(A45,[1]!TablaTransporte[#Data],2,FALSE),0) -> 0
...

Sheet cerramiento 
A1: CERRAMIENTO PROVISIONAL
A2: EQUIPOS | B2: CANT | C2: REND/DIA | D2: TARIFA/DIA | E2: VR.PARCIAL | F2: ML
F3: 510
A4: Machete con funda | B4: 1 | C4: 12 | D4: =IFERROR(VLOOKUP(A4,[1]!TablaEquipos[#Data],2,FALSE),0) -> 1500 | E4: =B4*C4*D4 -> 18000
A5: Lima triangular | B5: 1 | C5: 12 | D5: =IFERROR(VLOOKUP(A5,[1]!TablaEquipos[#Data],2,FALSE),0) -> 700 | E5: =B5*C5*D5 -> 8400
A6: Martillo | B6: 1 | C6: 12 | D6: =IFERROR(VLOOKUP(A6,[1]!TablaEquipos[#Data],2,FALSE),0) -> 700 | E6: =B6*C6*D6 -> 8400
A7: Pala | B7: 1 | C7: 12 | D7: =IFERROR(VLOOKUP(A7,[1]!TablaEquipos[#Data],2,FALSE),0) -> 700 | E7: =B7*C7*D7 -> 8400
A8: Barra | B8: 1 | C8: 12 | D8: =IFERROR(VLOOKUP(A8,[1]!TablaEquipos[#Data],2,FALSE),0) -> 1500 | E8: =B8*C8*D8 -> 18000
A9: Sierra circular | B9: 1 | C9: 12 | D9: =IFERROR(VLOOKUP(A9,[1]!TablaEquipos[#Data],2,FALSE),0) -> 15000 | E9: =B9*C9*D9 -> 180000
A10: Paladraga | B10: 2 | C10: 12 | D10: =IFERROR(VLOOKUP(A10,[1]!TablaEquipos[#Data],2,FALSE),0) -> 1500 | E10: =B10*C10*D10 -> 36000
A11: Alicate diablo | B11: 2 | C11: 12 | D11: =IFERROR(VLOOKUP(A11,[1]!TablaEquipos[#Data],2,FALSE),0) -> 500 | E11: =B11*C11*D11 -> 12000
A12: Alicate universal | B12: 1 | C12: 12 | D12: =IFERROR(VLOOKUP(A12,[1]!TablaEquipos[#Data],2,FALSE),0) -> 500 | E12: =B12*C12*D12 -> 6000
A13: Carretilla | B13: 2 | C13: 12 | D13: =IFERROR(VLOOKUP(A13,[1]!TablaEquipos[#Data],2,FALSE),0) -> 1500 | E13: =B13*C13*D13 -> 36000
B14: 2 | D14: =IFERROR(VLOOKUP(A14,[1]!TablaEquipos[#Data],2,FALSE),0) -> 0
B15: 2 | D15: =IFERROR(VLOOKUP(A15,[1]!TablaEquipos[#Data],2,FALSE),0) -> 0
B16: 2 | D16: =IFERROR(VLOOKUP(A16,[1]!TablaEquipos[#Data],2,FALSE),0) -> 0
B17: 2 | D17: =IFERROR(VLOOKUP(A17,[1]!TablaEquipos[#Data],2,FALSE),0) -> 0
F18: =SUM(E4:E17) -> 331200
A19: MATERIALES | B19: CANT | C19: REND/DIA | D19: TARIFA | E19: VR.PARCIAL
A20: madera redonda 3" x 2.5m | B20: 180 | D20: =IFERROR(VLOOKUP(A20,[1]!TablaMateriales[#Data],2,FALSE),0) -> 25000 | E20: =B20*D20 -> 4500000
A21: Grapa | B21: 4 | D21: =IFERROR(VLOOKUP(A21,[1]!TablaMateriales[#Data],2,FALSE),0) -> 15900 | E21: =B21*D21 -> 63600
A22: Alambre HG calibre 14 | B22: 55 | D22: =IFERROR(VLOOKUP(A22,[1]!TablaMateriales[#Data],2,FALSE),0) -> 14000 | E22: =B22*D22 -> 770000
A23: Tela verde de 2 metros | B23: 570 | D23: =IFERROR(VLOOKUP(A23,[1]!TablaMateriales[#Data],2,FALSE),0) -> 3800 | E23: =B23*D23 -> 2166000
D24: =IFERROR(VLOOKUP(A24,[1]!TablaMateriales[#Data],2,FALSE),0) -> 0 | E24: =B24*D24 -> 0
D25: =IFERROR(VLOOKUP(A25,[1]!TablaMateriales[#Data],2,FALSE),0) -> 0
D26: =IFERROR(VLOOKUP(A26,[1]!TablaMateriales[#Data],2,FALSE),0) -> 0
D27: =IFERROR(VLOOKUP(A27,[1]!TablaMateriales[#Data],2,FALSE),0) -> 0
D28: =IFERROR(VLOOKUP(A28,[1]!TablaMateriales[#Data],2,FALSE),0) -> 0
F29: =SUM(E20:E28) -> 7499600
A30: MANO DE OBRA | B30: CANT | C30: REND/DIA | D30: SALARIO | E30: VR.PARCIAL
A31: Capataz | B31: 1 | C31: 6.46 | D31: ='tabla salarial'!AS4 -> 555393.74 | E31: =B31*C31*D31 -> 3587843.6
A32: Hse | B32: 1 | C32: 6.46 | D32: ='tabla salarial'!AS4 -> 555393.74 | E32: =B32*C32*D32 -> 3587843.6
A33: Oficial construccion | B33: 1 | C33: 19.7 | D33: ='tabla salarial'!AS7 -> 371571.33 | E33: =B33*C33*D33 -> 7319955.2
A34: Auxiliar Administrativo | B34: 1 | C34: 6.46 | D34: ='tabla salarial'!AS8 -> 355821.88 | E34: =B34*C34*D34 -> 2298609.3
A35: Auxiliar civil | B35: 4 | C35: 19.7 | D35: ='tabla salarial'!AS9 -> 382109.06 | E35: =B35*C35*D35 -> 30110194
F36: =SUM(E31:E35) -> 46904446
A37: TRANSPORTE | B37: CANT | C37: REND/DIA | D37: TARIFA | E37: VR.PARCIAL
A38: Camión doble cabina | B38: 1 | C38: 1 | D38: =IFERROR(VLOOKUP(A38,[1]!TablaTransporte[#Data],2,FALSE),0) -> 550000 | E38: =B38*C38*D38 -> 550000
A39: buseta acpm | B39: 1 | C39: 6 | D39: 550000 | E39: =B39*C39*D39 -> 3300000
D40: =IFERROR(VLOOKUP(A40,[1]!TablaTransporte[#Data],2,FALSE),0) -> 0
...

Sheet campamento
A1: CAMPAMENTO DE OBRA
A2: EQUIPOS | B2: CANT | C2: REND/DIA | D2: TARIFA/DIA | E2: VR.PARCIAL | F2: global
F3: 9
A4: Machete | B4: 2 | C4: 24 | D4: =IFERROR(VLOOKUP(A4,[1]!TablaEquipos[#Data],2,FALSE),0) -> 1500 | E4: =B4*C4*D4 -> 72000
A5: Martillo | B5: 2 | C5: 24 | D5: =IFERROR(VLOOKUP(A5,[1]!TablaEquipos[#Data],2,FALSE),0) -> 700 | E5: =B5*C5*D5 -> 33600
A6: Pala | B6: 1 | C6: 24 | D6: =IFERROR(VLOOKUP(A6,[1]!TablaEquipos[#Data],2,FALSE),0) -> 700 | E6: =B6*C6*D6 -> 16800
A7: Barra | B7: 1 | C7: 24 | D7: =IFERROR(VLOOKUP(A7,[1]!TablaEquipos[#Data],2,FALSE),0) -> 1500 | E7: =B7*C7*D7 -> 36000
A8: Sierra circular | B8: 1 | C8: 24 | D8: =IFERROR(VLOOKUP(A8,[1]!TablaEquipos[#Data],2,FALSE),0) -> 15000 | E8: =B8*C8*D8 -> 360000
A9: Paladraga | B9: 2 | C9: 24 | D9: =IFERROR(VLOOKUP(A9,[1]!TablaEquipos[#Data],2,FALSE),0) -> 1500 | E9: =B9*C9*D9 -> 72000
A10: Alicate diablo | B10: 1 | C10: 24 | D10: =IFERROR(VLOOKUP(A10,[1]!TablaEquipos[#Data],2,FALSE),0) -> 500 | E10: =B10*C10*D10 -> 12000
A11: Alicate universal | B11: 1 | C11: 24 | D11: =IFERROR(VLOOKUP(A11,[1]!TablaEquipos[#Data],2,FALSE),0) -> 500 | E11: =B11*C11*D11 -> 12000
A12: Carretilla | B12: 2 | C12: 24 | D12: =IFERROR(VLOOKUP(A12,[1]!TablaEquipos[#Data],2,FALSE),0) -> 1500 | E12: =B12*C12*D12 -> 72000
A13: Carpa plastica 4x4 | B13: 2 | C13: 240 | D13: =IFERROR(VLOOKUP(A13,[1]!TablaEquipos[#Data],2,FALSE),0) -> 27500 | E13: =B13*C13*D13 -> 13200000
A14: Carpa plastica 6x4 | B14: 1 | C14: 240 | D14: =IFERROR(VLOOKUP(A14,[1]!TablaEquipos[#Data],2,FALSE),0) -> 30000 | E14: =B14*C14*D14 -> 7200000
A15: Mesa de madera | B15: 2 | C15: 240 | D15: =IFERROR(VLOOKUP(A15,[1]!TablaEquipos[#Data],2,FALSE),0) -> 5000 | E15: =B15*C15*D15 -> 2400000
... A25: Extintor Co2 | B25: 1 | C25: 240 | D25: =IFERROR(VLOOKUP(A25,[1]!TablaEquipos[#Data],2,FALSE),0) -> 1500 | E25: =B25*C25*D25 -> 360000
C26: 240
C27: 240
D28: =IFERROR(VLOOKUP(A28,[1]!TablaEquipos[#Data],2,FALSE),0) -> 0 | E28: =B28*C28*D28 -> 0
F29: =SUM(E4:E28) -> 51974280
A30: MATERIALES | B30: CANT | C30: REND/DIA | D30: TARIFA | E30: VR.PARCIAL | XEX30: =SUM(D28) -> 0
A31: Listón de madera 2 x 1 x 3 | B31: 50 | D31: =IFERROR(VLOOKUP(A31,[1]!TablaMateriales[#Data],2,FALSE),0) -> 20000 | E31: =B31*D31 -> 1000000
A32: Puntilla de 2,5" | B32: 10 | D32: =IFERROR(VLOOKUP(A32,[1]!TablaMateriales[#Data],2,FALSE),0) -> 9500 | E32: =B32*D32 -> 95000
A33: Cinta de seguridad amarilla/negra x 500 | B33: 5 | D33: =IFERROR(VLOOKUP(A33,[1]!TablaMateriales[#Data],2,FALSE),0) -> 55000 | E33: =B33*D33 -> 275000
A34: Grapa | B34: 5 | D34: =IFERROR(VLOOKUP(A34,[1]!TablaMateriales[#Data],2,FALSE),0) -> 15900 | E34: =B34*D34 -> 79500
A35: Plástico negro | B35: 20 | D35: =IFERROR(VLOOKUP(A35,[1]!TablaMateriales[#Data],2,FALSE),0) -> 9500 | E35: =B35*D35 -> 190000
D36: =IFERROR(VLOOKUP(A36,[1]!TablaMateriales[#Data],2,FALSE),0) -> 0
D37: =IFERROR(VLOOKUP(A37,[1]!TablaMateriales[#Data],2,FALSE),0) -> 0
F38: =SUM(E31:E37) -> 1639500
A39: MANO DE OBRA | B39: CANT | C39: REND/DIA | D39: SALARIO | E39: VR.PARCIAL
A40: Capataz | B40: 1 | C40: 9.4 | D40: ='tabla salarial'!AS4 -> 555393.74 | E40: =B40*C40*D40 -> 5220701.2
A41: Hse | B41: 1 | C41: 9.4 | D41: ='tabla salarial'!AS4 -> 555393.74 | E41: =B41*C41*D41 -> 5220701.2
A42: Oficial construccion | B42: 1 | C42: 28.2 | D42: ='tabla salarial'!AS7 -> 371571.33 | E42: =B42*C42*D42 -> 10478311
A43: Auxiliar Administrativo | B43: 1 | C43: 9.4 | D43: ='tabla salarial'!AS8 -> 355821.88 | E43: =B43*C43*D43 -> 3344725.6
A44: Auxiliar civil | B44: 2 | C44: 28.2 | D44: ='tabla salarial'!AS9 -> 382109.06 | E44: =B44*C44*D44 -> 21550951
F45: =SUM(E40:E44) -> 45815390
A46: TRANSPORTE | B46: CANT | C46: REND/DIA | D46: TARIFA | E46: VR.PARCIAL
A47: Camión doble cabina | B47: 1 | C47: 2 | D47: =IFERROR(VLOOKUP(A47,[1]!TablaTransporte[#Data],2,FALSE),0) -> 550000 | E47: =B47*C47*D47 -> 1100000
A48: buseta acpm | B48: 1 | C48: 7 | D48: 550000 | E48: =B48*C48*D48 -> 3850000
F49: =SUM(E47:E48) -> 4950000
...

Sheet andamios
A1: ARMADO, UTILIZACIÓN Y DESARMADO DE ANDAMIOS TIPO LAYDER
A2: EQUIPOS | B2: CANT | C2: REND/DIA | D2: TARIFA/DIA | E2: VR.PARCIAL | F2: seccion
F3: 295
A4: Almadana en bronce | B4: 1 | C4: 38 | D4: =IFERROR(VLOOKUP(A4,[1]!TablaEquipos[#Data],2,FALSE),0) -> 450 | E4: =B4*C4*D4 -> 17100
A5: Andamios Layher | B5: 1 | C5: 295 | D5: =IFERROR(VLOOKUP(A5,[1]!TablaEquipos[#Data],2,FALSE),0) -> 135000 | E5: =B5*C5*D5 -> 39825000
A6: Arnés de seguridad y Erlingas | B6: 1 | C6: 38 | D6: =IFERROR(VLOOKUP(A6,[1]!TablaEquipos[#Data],2,FALSE),0) -> 9000 | E6: =B6*C6*D6 -> 342000
A7: Nivel torpedo | B7: 2 | C7: 38 | D7: =IFERROR(VLOOKUP(A7,[1]!TablaEquipos[#Data],2,FALSE),0) -> 1000 | E7: =B7*C7*D7 -> 76000
A8: Carretilla | B8: 2 | C8: 38 | D8: =IFERROR(VLOOKUP(A8,[1]!TablaEquipos[#Data],2,FALSE),0) -> 1500 | E8: =B8*C8*D8 -> 114000
A9: Colombina | B9: 12 | C9: 38 | D9: =IFERROR(VLOOKUP(A9,[1]!TablaEquipos[#Data],2,FALSE),0) -> 1000 | E9: =B9*C9*D9 -> 456000
F13: =SUM(E4:E11) -> 40830100
A14: MATERIALES | B14: CANT | C14: REND/DIA | D14: TARIFA | E14: VR.PARCIAL
A15: Cinta de seguridad amarilla/negra x 500 | B15: 2 | D15: =IFERROR(VLOOKUP(A15,[1]!TablaMateriales[#Data],2,FALSE),0) -> 55000 | E15: =B15*D15 -> 110000
D16: =IFERROR(VLOOKUP(A16,[1]!TablaMateriales[#Data],2,FALSE),0) -> 0
D17: =IFERROR(VLOOKUP(A17,[1]!TablaMateriales[#Data],2,FALSE),0) -> 0
D18: =IFERROR(VLOOKUP(A18,[1]!TablaMateriales[#Data],2,FALSE),0) -> 0
D19: =IFERROR(VLOOKUP(A19,[1]!TablaMateriales[#Data],2,FALSE),0) -> 0
D20: =IFERROR(VLOOKUP(A20,[1]!TablaMateriales[#Data],2,FALSE),0) -> 0
F21: =SUM(E15:E20) -> 110000
A22: MANO DE OBRA | B22: CANT | C22: REND/DIA | D22: SALARIO | E22: VR.PARCIAL
A23: Capataz | B23: 1 | C23: 10.6 | D23: ='tabla salarial'!AS4 -> 555393.74 | E23: =B23*C23*D23 -> 5887173.7
A24: Hse | B24: 1 | C24: 10.6 | D24: ='tabla salarial'!AS4 -> 555393.74 | E24: =B24*C24*D24 -> 5887173.7
A25: cordinador de altura | B25: 1 | C25: 10.6 | D25: ='tabla salarial'!AS4 -> 555393.74 | E25: =B25*C25*D25 -> 5887173.7
A26: rescatista | B26: 1 | C26: 44.7 | D26: ='tabla salarial'!AS5 -> 443956.94 | E26: =C26*D26 -> 19844875
A27: Andamiero | B27: 1 | C27: 44.7 | D27: ='tabla salarial'!AS6 -> 407197.8 | E27: =B27*C27*D27 -> 18201742
A28: Oficial construccion | B28: 1 | D28: ='tabla salarial'!AS7 -> 371571.33 | E28: =B28*C28*D28 -> 0
A29: Auxiliar Administrativo | B29: 1 | C29: 10.6 | D29: ='tabla salarial'!AS8 -> 355821.88 | E29: =B29*C29*D29 -> 3771711.9
A30: Auxiliar civil | B30: 2 | D30: ='tabla salarial'!AS9 -> 382109.06 | E30: =B30*C30*D30 -> 0
F31: =SUM(E23:E30) -> 59479850
A32: TRANSPORTE | B32: CANT | C32: REND/DIA | D32: TARIFA | E32: VR.PARCIAL
A33: Camión doble cabina | B33: 1 | C33: 10 | D33: =IFERROR(VLOOKUP(A33,[1]!TablaTransporte[#Data],2,FALSE),0) -> 550000 | E33: =B33*C33*D33 -> 5500000
F34: =E33 -> 5500000
F35: =F13+F21+F31+F34 -> 1.0591995e+08
F36: =F35*A36 -> 0
F37: =F35+F36 -> 1.0591995e+08
F38: =F37*A38 -> 0
F39: =F37+F38 -> 1.0591995e+08
F40: =F39/F3 -> 359050.68

Sheet topografia
A1: REPLANTEO TOPOGRÁFICO
A2: EQUIPOS | B2: CANT | C2: REND/DIA | D2: TARIFA/DIA | E2: VR.PARCIAL | F2: jornada
F3: 10
A4: Machete | B4: 2 | C4: 10 | D4: 2500 | E4: =B4*C4*D4 -> 50000
A5: Martillo | B5: 1 | C5: 10 | D5: =IFERROR(VLOOKUP(A5,[1]!TablaEquipos[#Data],2,FALSE),0) -> 700 | E5: =B5*C5*D5 -> 7000
A6: Carretilla | B6: 1 | C6: 10 | D6: 4500 | E6: =B6*C6*D6 -> 45000
A7: Camilla primeros auxilios | B7: 1 | C7: 10 | D7: 2500 | E7: =B7*C7*D7 -> 25000
A8: Botiquin primeros auxilios | B8: 1 | C8: 10 | D8: 2500 | E8: =B8*C8*D8 -> 25000
A9: Equipo topografico | B9: 1 | C9: 10 | D9: 500000 | E9: =B9*C9*D9 -> 5000000
D13: =IFERROR(VLOOKUP(A13,[1]!TablaEquipos[#Data],2,FALSE),0) -> 0
D14: =IFERROR(VLOOKUP(A14,[1]!TablaEquipos[#Data],2,FALSE),0) -> 0
D15: =IFERROR(VLOOKUP(A15,[1]!TablaEquipos[#Data],2,FALSE),0) -> 0
D16: =IFERROR(VLOOKUP(A16,[1]!TablaEquipos[#Data],2,FALSE),0) -> 0
D17: =IFERROR(VLOOKUP(A17,[1]!TablaEquipos[#Data],2,FALSE),0) -> 0
A18: =#REF!*#REF! -> #REF! | F18: =SUM(E4:E17) -> 5152000
A19: MATERIALES | B19: CANT | C19: REND/DIA | D19: TARIFA | E19: =B22*D22 -> 30000
A20: Listón de madera 2 x 1 x 3 | B20: 50 | D20: =IFERROR(VLOOKUP(A20,[1]!TablaMateriales[#Data],2,FALSE),0) -> 20000 | E20: =B20*D20 -> 1000000
A21: Puntilla de 2,5" | B21: 2 | C21: 10 | D21: =IFERROR(VLOOKUP(A21,[1]!TablaMateriales[#Data],2,FALSE),0) -> 9500 | E21: =B21*D21 -> 19000
A22: Clavo de acero de 3" | B22: 2 | C22: 10 | D22: =IFERROR(VLOOKUP(A22,[1]!TablaMateriales[#Data],2,FALSE),0) -> 15000 | E22: =B22*D22 -> 30000
A23: Pintura en aerosol | B23: 20 | C23: 10 | D23: =IFERROR(VLOOKUP(A23,[1]!TablaMateriales[#Data],2,FALSE),0) -> 20000 | E23: =B23*D23 -> 400000
F33: =SUM(E19:E32) -> 1479000
A34: MANO DE OBRA | B34: CANT | C34: REND/DIA | D34: SALARIO | E34: VR.PARCIAL
A35: Capataz | B35: 1 | D35: ='tabla salarial'!AS4 -> 555393.74 | E35: =B35*C35*D35 -> 0
A36: Hse | B36: 1 | D36: ='tabla salarial'!AS4 -> 555393.74 | E36: =B36*C36*D36 -> 0
A37: Topografo | B37: 1 | C37: 13 | D37: ='tabla salarial'!AS4 -> 555393.74 | E37: =B37*C37*D37 -> 7220118.6
A38: Cadenero 1 | B38: 1.5 | C38: 13 | D38: ='tabla salarial'!AS6 -> 407197.8 | E38: =B38*C38*D38 -> 7940357.2
A39: Andamiero | B39: 2 | D39: ='tabla salarial'!AS6 -> 407197.8 | E39: =B39*C39*D39 -> 0
A40: Oficial construccion | B40: 1 | D40: ='tabla salarial'!AS7 -> 371571.33 | E40: =B40*C40*D40 -> 0
A41: Auxiliar Administrativo | B41: 1 | D41: ='tabla salarial'!AS8 -> 355821.88 | E41: =B41*C41*D41 -> 0
A42: Auxiliar civil | B42: 1 | C42: 13 | D42: ='tabla salarial'!AS9 -> 382109.06 | E42: =B42*C42*D42 -> 4967417.8
A43: 3 | F43: =SUM(E35:E42) -> 20127894
A44: TRANSPORTE | B44: CANT | C44: REND/DIA | D44: TARIFA | E44: VR.PARCIAL
A45: Buseta | B45: 1 | C45: 3 | D45: 550000 | E45: =B45*C45*D45 -> 1650000
F46: =E45 -> 1650000
F47: =F18+F33+F43+F46 -> 28408894
F48: =F47*A48 -> 0
F49: =F47+F48 -> 28408894
F50: =F49*A50 -> 0
F51: =F49+F50 -> 28408894
F52: =F51/F3 -> 2840889.4

Sheet acarreobotadero
A1: ACARREO MATERIAL BOTADERO
A2: EQUIPOS | B2: CANT | C2: REND/DIA | D2: TARIFA/DIA | E2: VR.PARCIAL | F2: m3/km
F3: 57
A4: Pala | B4: 2 | C4: 3 | D4: =IFERROR(VLOOKUP(A4,[1]!TablaEquipos[#Data],2,FALSE),0) -> 700 | E4: =B4*C4*D4 -> 4200
F10: =SUM(E4:E9) -> 4200
A11: MATERIALES | B11: CANT | C11: REND/DIA | D11: TARIFA | E11: VR.PARCIAL
A12: Plastico negro | B12: 50 | D12: =IFERROR(VLOOKUP(A12,[1]!TablaMateriales[#Data],2,FALSE),0) -> 9500 | E12: =B12*D12 -> 475000
D13: =IFERROR(VLOOKUP(A13,[1]!TablaMateriales[#Data],2,FALSE),0) -> 0
F16: =SUM(E12:E13) -> 475000
A17: MANO DE OBRA | B17: CANT | C17: REND/DIA | D17: SALARIO | E17: VR.PARCIAL
A18: Capataz | B18: 1 | C18: 0.38 | D18: ='tabla salarial'!AS4 -> 555393.74 | E18: =B18*C18*D18 -> 211049.62
A19: Hse | B19: 1 | C19: 0.38 | D19: ='tabla salarial'!AS4 -> 555393.74 | E19: =B19*C19*D19 -> 211049.62
A20: Oficial construccion | B20: 1 | C20: 0.38 | D20: ='tabla salarial'!AS7 -> 371571.33 | E20: =B20*C20*D20 -> 141197.11
A21: Auxiliar Administrativo | B21: 1 | C21: 0.38 | D21: ='tabla salarial'!AS8 -> 355821.88 | E21: =B21*C21*D21 -> 135212.31
A22: Auxiliar civil | B22: 1 | C22: 4.7 | D22: ='tabla salarial'!AS9 -> 382109.06 | E22: =B22*C22*D22 -> 1795912.6
A23: 3 | F23: =SUM(E18:E22) -> 2494421.2
A24: TRANSPORTE | B24: CANT | C24: REND/DIA | D24: TARIFA | E24: VR.PARCIAL
A26: Acarreo por km | B26: 1 | C26: 57 | D26: =IFERROR(VLOOKUP(A26,[1]!TablaTransporte[#Data],2,FALSE),0) -> 65000 | E26: =B26*C26*D26 -> 3705000
A27: Retroexcavadora de llantas | B27: 1 | C27: 1 | D27: =IFERROR(VLOOKUP(A27,[1]!TablaTransporte[#Data],2,FALSE),0) -> 1330000 | E27: =B27*C27*D27 -> 1330000
D28: =IFERROR(VLOOKUP(A28,[1]!TablaTransporte[#Data],2,FALSE),0) -> 0
F29: =SUM(E25:E28) -> 5035000
F30: =F10+F16+F23+F29 -> 8008621.2
F31: =F30*A31 -> 0
F32: =F30+F31 -> 8008621.2
F33: =F32*A33 -> 0
F34: =F32+F33 -> 8008621.2
F35: =F34/F3 -> 140502.13

Sheet movimiento tierra
A1: MOVIMIENTO DE TIERRA INTERNO
A2: EQUIPOS | B2: CANT | C2: REND/DIA | D2: TARIFA/DIA | E2: VR.PARCIAL | F2: JORNADA
F3: 62
A4: Pala | B4: 2 | C4: 62 | D4: =IFERROR(VLOOKUP(A4,[1]!TablaEquipos[#Data],2,FALSE),0) -> 700 | E4: =B4*C4*D4 -> 86800
A5: Barra | B5: 4 | C5: 62 | D5: =IFERROR(VLOOKUP(A5,[1]!TablaEquipos[#Data],2,FALSE),0) -> 1500 | E5: =B5*C5*D5 -> 372000
A6: Carretilla | B6: 2 | C6: 62 | D6: =IFERROR(VLOOKUP(A6,[1]!TablaEquipos[#Data],2,FALSE),0) -> 1500 | E6: =B6*C6*D6 -> 186000
A7: Colombina | B7: 12 | C7: 62 | D7: =IFERROR(VLOOKUP(A7,[1]!TablaEquipos[#Data],2,FALSE),0) -> 1000 | E7: =B7*C7*D7 -> 744000
A8: Avisos de seguridad | B8: 20 | C8: 62 | D8: 500 | E8: =B8*C8*D8 -> 620000
A9: Paletas | B9: 2 | C9: 62 | D9: 500 | E9: =B9*C9*D9 -> 62000
D10: 40000 | E10: =B10*C10*D10 -> 0
D13: =IFERROR(VLOOKUP(A13,[1]!TablaEquipos[#Data],2,FALSE),0) -> 0
D14: =IFERROR(VLOOKUP(A14,[1]!TablaEquipos[#Data],2,FALSE),0) -> 0
D15: =IFERROR(VLOOKUP(A15,[1]!TablaEquipos[#Data],2,FALSE),0) -> 0
F16: =SUM(E4:E15) -> 2070800
A17: MATERIALES | B17: CANT | C17: REND/DIA | D17: TARIFA | E17: VR.PARCIAL
A18: Plástico negro | B18: 150 | D18: =IFERROR(VLOOKUP(A18,[1]!TablaMateriales[#Data],2,FALSE),0) -> 9500 | E18: =B18*D18 -> 1425000
A19: Chaleco Reflectivo | B19: 2 | D19: =IFERROR(VLOOKUP(A19,[1]!TablaMateriales[#Data],2,FALSE),0) -> 20000 | E19: =B19*D19 -> 40000
D22: =IFERROR(VLOOKUP(A22,[1]!TablaMateriales[#Data],2,FALSE),0) -> 0
F23: =SUM(E18:E22) -> 1465000
A24: MANO DE OBRA | B24: CANT | C24: REND/DIA | D24: SALARIO | E24: VR.PARCIAL
A25: Capataz | B25: 1 | C25: 28.8 | D25: ='tabla salarial'!AS4 -> 555393.74 | E25: =B25*C25*D25 -> 15995340
A26: Hse | B26: 1 | C26: 28.8 | D26: ='tabla salarial'!AS4 -> 555393.74 | E26: =B26*C26*D26 -> 15995340
A27: Oficial construccion | B27: 1 | C27: 86 | D27: ='tabla salarial'!AS7 -> 371571.33 | E27: =B27*C27*D27 -> 31955134
A28: Oficinista 2 | B28: 1 | C28: 28.8 | D28: ='tabla salarial'!AS8 -> 355821.88 | E28: =B28*C28*D28 -> 10247670
A29: Auxiliar civil | B29: 2 | C29: 86 | D29: ='tabla salarial'!AS9 -> 382109.06 | E29: =B29*C29*D29 -> 65722758
F30: =SUM(E25:E29) -> 1.3991624e+08
A31: TRANSPORTE | B31: CANT | C31: REND/DIA | D31: TARIFA | E31: VR.PARCIAL
A32: Buseta | B32: 1 | C32: 20 | D32: 550000 | E32: =B32*C32*D32 -> 11000000
A33: retro excavadora de llanta | B33: 1 | C33: 62 | D33: =IFERROR(VLOOKUP(A33,[1]!TablaTransporte[#Data],2,FALSE),0) -> 1330000 | E33: =B33*C33*D33 -> 82460000
A34: Volqueta de 14 m³ | B34: 1 | C34: 62 | D34: =IFERROR(VLOOKUP(A34,[1]!TablaTransporte[#Data],2,FALSE),0) -> 1350000 | E34: =B34*C34*D34 -> 83700000
F35: =SUM(E32:E34) -> 177160000
F36: =F16+F23+F30+F35 -> 3.2061204e+08
F37: =F36*A37 -> 0
F38: =F36+F37 -> 3.2061204e+08
F39: =F38*A39 -> 0
F40: =F38+F39 -> 3.2061204e+08
F41: =F40/F3 -> 5171162

Sheet  excavacion -1,20mts
A1: EXCAVACIÓN MANUAL MENOR A 1,20MTS
A2: EQUIPOS | B2: CANT | C2: REND/DIA | D2: TARIFA/DIA | E2: VR.PARCIAL | F2: M3
F3: 657
A4: Pala | B4: 8 | C4: 85 | D4: =IFERROR(VLOOKUP(A4,[1]!TablaEquipos[#Data],2,FALSE),0) -> 700 | E4: =B4*C4*D4 -> 476000
A5: Pica | B5: 8 | C5: 85 | D5: =IFERROR(VLOOKUP(A5,[1]!TablaEquipos[#Data],2,FALSE),0) -> 700 | E5: =B5*C5*D5 -> 476000
A6: Palín | B6: 8 | C6: 85 | D6: =IFERROR(VLOOKUP(A6,[1]!TablaEquipos[#Data],2,FALSE),0) -> 700 | E6: =B6*C6*D6 -> 476000
A7: Paladraga | B7: 4 | C7: 85 | D7: =IFERROR(VLOOKUP(A7,[1]!TablaEquipos[#Data],2,FALSE),0) -> 1500 | E7: =B7*C7*D7 -> 510000
A8: Barra | B8: 4 | C8: 85 | D8: =IFERROR(VLOOKUP(A8,[1]!TablaEquipos[#Data],2,FALSE),0) -> 1500 | E8: =B8*C8*D8 -> 510000
A9: Herramientero | B9: 1 | C9: 85 | D9: =IFERROR(VLOOKUP(A9,[1]!TablaEquipos[#Data],2,FALSE),0) -> 1500 | E9: =B9*C9*D9 -> 127500
A10: Carretilla | B10: 6 | C10: 85 | D10: =IFERROR(VLOOKUP(A10,[1]!TablaEquipos[#Data],2,FALSE),0) -> 1500 | E10: =B10*C10*D10 -> 765000
A11: Avisos de seguridad | B11: 30 | C11: 85 | D11: 500 | E11: =B11*C11*D11 -> 1275000
XFD12: =SUM(G12:XFC12) -> 0
D17: =IFERROR(VLOOKUP(A17,[1]!TablaEquipos[#Data],2,FALSE),0) -> 0 | E17: =B17*C17*D17 -> 0
D18: =IFERROR(VLOOKUP(A18,[1]!TablaEquipos[#Data],2,FALSE),0) -> 0 | E18: =B18*C18*D18 -> 0
F19: =SUM(E4:E18) -> 4615500
A20: MATERIALES | B20: CANT | C20: REND/DIA | D20: TARIFA | E20: VR.PARCIAL
A21: Listón de madera 2 x 4 x 3 | B21: 20 | D21: =IFERROR(VLOOKUP(A21,[1]!TablaMateriales[#Data],2,FALSE),0) -> 35000 | E21: =B21*D21 -> 700000
A22: Listón de madera 2 x 1 x 3 | B22: 30 | D22: =IFERROR(VLOOKUP(A22,[1]!TablaMateriales[#Data],2,FALSE),0) -> 20000 | E22: =B22*D22 -> 600000
A23: Puntilla de 3,5" | B23: 5 | D23: =IFERROR(VLOOKUP(A23,[1]!TablaMateriales[#Data],2,FALSE),0) -> 9500 | E23: =B23*D23 -> 47500
A24: Cinta de seguridad amarilla/negra x 500 | B24: 2 | D24: =IFERROR(VLOOKUP(A24,[1]!TablaMateriales[#Data],2,FALSE),0) -> 55000 | E24: =B24*D24 -> 110000
A25: Plastico negro | B25: 150 | D25: 9500 | E25: =B25*D25 -> 1425000
D28: =IFERROR(VLOOKUP(A28,[1]!TablaMateriales[#Data],2,FALSE),0) -> 0
D29: =IFERROR(VLOOKUP(A29,[1]!TablaMateriales[#Data],2,FALSE),0) -> 0
D30: =IFERROR(VLOOKUP(A30,[1]!TablaMateriales[#Data],2,FALSE),0) -> 0
D31: =IFERROR(VLOOKUP(A31,[1]!TablaMateriales[#Data],2,FALSE),0) -> 0
F32: =SUM(E21:E31) -> 2882500
A33: MANO DE OBRA | B33: CANT | C33: REND/DIA | D33: SALARIO | E33: VR.PARCIAL
A34: Capataz | B34: 1 | C34: 34 | D34: ='tabla salarial'!AS4 -> 555393.74 | E34: =B34*C34*D34 -> 18883387
A35: Hse | B35: 1 | C35: 34 | D35: ='tabla salarial'!AS4 -> 555393.74 | E35: =B35*C35*D35 -> 18883387
A36: Oficial construccion | B36: 2 | C36: 102 | D36: ='tabla salarial'!AS7 -> 371571.33 | E36: =B36*C36*D36 -> 75800551
A37: Oficinista 2 | B37: 1 | C37: 34 | D37: ='tabla salarial'!AS8 -> 355821.88 | E37: =B37*C37*D37 -> 12097944
A38: Auxiliar civil | B38: 8 | C38: 102 | D38: ='tabla salarial'!AS9 -> 382109.06 | E38: =B38*C38*D38 -> 3.1180099e+08
A39: 3 | F39: =SUM(E34:E38) -> 4.3746626e+08
A40: TRANSPORTE | B40: CANT | C40: REND/DIA | D40: TARIFA | E40: VR.PARCIAL
A41: Buseta | B41: 1 | C41: 85 | D41: 600000 | E41: =B41*C41*D41 -> 51000000
A42: Retroexcavadora con llantas | B42: 1 | C42: 4 | D42: 1330000 | E42: =B42*C42*D42 -> 5320000
A43: Volqueta de 14 m³ | B43: 1 | C43: 4 | D43: 1390000 | E43: =B43*C43*D43 -> 5560000
A44: Traslado de equipos | B44: 1 | C44: 1 | D44: 1650000 | E44: =B44*C44*D44 -> 1650000
F47: =SUM(E41:E46) -> 63530000
F48: =F19+F32+F39+F47 -> 5.0849426e+08
...

Sheet excavación +1,20mts
A1: EXCAVACIÓN MANUAL MAYOR A 1,20MTS
A2: EQUIPOS | B2: CANT | C2: REND/DIA | D2: TARIFA/DIA | E2: VR.PARCIAL | F2: M3
F3: 525
A4: Machete | B4: 1 | C4: 15 | D4: =IFERROR(VLOOKUP(A4,[1]!TablaEquipos[#Data],2,FALSE),0) -> 1500 | E4: =B4*C4*D4 -> 22500
A5: Martillo | B5: 1 | C5: 15 | D5: =IFERROR(VLOOKUP(A5,[1]!TablaEquipos[#Data],2,FALSE),0) -> 700 | E5: =B5*C5*D5 -> 10500
A6: Pala | B6: 8 | C6: 87.5 | D6: =IFERROR(VLOOKUP(A6,[1]!TablaEquipos[#Data],2,FALSE),0) -> 700 | E6: =B6*C6*D6 -> 490000
A7: Pica | B7: 8 | C7: 87.5 | D7: =IFERROR(VLOOKUP(A7,[1]!TablaEquipos[#Data],2,FALSE),0) -> 700 | E7: =B7*C7*D7 -> 490000
A8: Palín | B8: 8 | C8: 87.5 | D8: =IFERROR(VLOOKUP(A8,[1]!TablaEquipos[#Data],2,FALSE),0) -> 700 | E8: =B8*C8*D8 -> 490000
A9: Paladraga | B9: 2 | C9: 40 | D9: =IFERROR(VLOOKUP(A9,[1]!TablaEquipos[#Data],2,FALSE),0) -> 1500 | E9: =B9*C9*D9 -> 120000
A10: Barra | B10: 2 | C10: 87.5 | D10: =IFERROR(VLOOKUP(A10,[1]!TablaEquipos[#Data],2,FALSE),0) -> 1500 | E10: =B10*C10*D10 -> 262500
A11: Herramientero | B11: 1 | C11: 87.5 | D11: =IFERROR(VLOOKUP(A11,[1]!TablaEquipos[#Data],2,FALSE),0) -> 1500 | E11: =B11*C11*D11 -> 131250
A12: Sierra circular | B12: 1 | C12: 15 | D12: =IFERROR(VLOOKUP(A12,[1]!TablaEquipos[#Data],2,FALSE),0) -> 15000 | E12: =B12*C12*D12 -> 225000
A13: Carretilla | B13: 6 | C13: 87.5 | D13: =IFERROR(VLOOKUP(A13,[1]!TablaEquipos[#Data],2,FALSE),0) -> 1500 | E13: =B13*C13*D13 -> 787500
A14: Balde concretero | B14: 12 | C14: 87.5 | D14: =IFERROR(VLOOKUP(A14,[1]!TablaEquipos[#Data],2,FALSE),0) -> 500 | E14: =B14*C14*D14 -> 525000
A15: Avisos de seguridad | B15: 30 | C15: 87.5 | D15: =IFERROR(VLOOKUP(A15,[1]!TablaEquipos[#Data],2,FALSE),0) -> 1000 | E15: =B15*C15*D15 -> 2625000
E16: =B16*C16*D16 -> 0
D18: =IFERROR(VLOOKUP(A18,[1]!TablaEquipos[#Data],2,FALSE),0) -> 0 | E18: =B18*C18*D18 -> 0
D19: =IFERROR(VLOOKUP(A19,[1]!TablaEquipos[#Data],2,FALSE),0) -> 0 | E19: =B19*C19*D19 -> 0
F20: =SUM(E4:E19) -> 6179250
A21: MATERIALES | B21: CANT | C21: REND/DIA | D21: TARIFA | E21: VR.PARCIAL
A22: Listón de madera 2 x 4 x 3 | B22: 20 | D22: =IFERROR(VLOOKUP(A22,[1]!TablaMateriales[#Data],2,FALSE),0) -> 35000 | E22: =B22*D22 -> 700000
A23: Listón de madera 2 x 1 x 3 | B23: 30 | D23: =IFERROR(VLOOKUP(A23,[1]!TablaMateriales[#Data],2,FALSE),0) -> 20000 | E23: =B23*D23 -> 600000
A24: Tabla | B24: 20 | D24: 45000 | E24: =B24*D24 -> 900000
A25: Puntilla de 3,5" | B25: 5 | D25: =IFERROR(VLOOKUP(A25,[1]!TablaMateriales[#Data],2,FALSE),0) -> 9500 | E25: =B25*D25 -> 47500
A26: Cinta de seguridad amarilla/negra x 500 | B26: 4 | D26: =IFERROR(VLOOKUP(A26,[1]!TablaMateriales[#Data],2,FALSE),0) -> 55000 | E26: =B26*D26 -> 220000
A27: Cabo para pala | B27: 10 | D27: 20000 | E27: =B27*D27 -> 200000
A28: Manila 5/16 | B28: 100 | D28: =IFERROR(VLOOKUP(A28,[1]!TablaMateriales[#Data],2,FALSE),0) -> 2850 | E28: =B28*D28 -> 285000
A29: Acpm | B29: 50 | D29: =IFERROR(VLOOKUP(A29,[1]!TablaMateriales[#Data],2,FALSE),0) -> 0 | E29: =B29*D29 -> 0
D35: =IFERROR(VLOOKUP(A35,[1]!TablaMateriales[#Data],2,FALSE),0) -> 0
D36: =IFERROR(VLOOKUP(A36,[1]!TablaMateriales[#Data],2,FALSE),0) -> 0
F37: =SUM(E22:E36) -> 2952500
A38: MANO DE OBRA | B38: CANT | C38: REND/DIA | D38: SALARIO | E38: VR.PARCIAL
A39: Capataz | B39: 1 | C39: 40 | D39: ='tabla salarial'!AS4 -> 555393.74 | E39: =B39*C39*D39 -> 22215750
A40: Hse | B40: 1 | C40: 40 | D40: ='tabla salarial'!AS4 -> 555393.74 | E40: =B40*C40*D40 -> 22215750
A41: Rescatista | B41: 1 | C41: 63 | D41: ='tabla salarial'!AS5 -> 443956.94 | E41: =B41*C41*D41 -> 27969287
A42: Oficial construccion | B42: 2 | C42: 121 | D42: ='tabla salarial'!AS7 -> 371571.33 | E42: =B42*C42*D42 -> 89920262
A43: auxiliar administracion | B43: 1 | C43: 40 | D43: ='tabla salarial'!AS8 -> 355821.88 | E43: =B43*C43*D43 -> 14232875
A44: Auxiliar civil | B44: 8 | C44: 121 | D44: ='tabla salarial'!AS9 -> 382109.06 | E44: =B44*C44*D44 -> 3.6988157e+08
A45: 3 | F45: =SUM(E39:E44) -> 5.4643549e+08
A46: TRANSPORTE | B46: CANT | C46: REND/DIA | D46: TARIFA | E46: VR.PARCIAL
...

Sheet excavación sin presencia
A1: EXCAVACIÓN MECANICA SIN PRESENCIA DE TUBERÍA O FACILIDAD ENTERRADA
A2: EQUIPOS | B2: CANT | C2: REND/DIA | D2: TARIFA/DIA | E2: VR.PARCIAL | F2: M3
F3: 29
A4: Pala | B4: 2 | C4: 0.5 | D4: =IFERROR(VLOOKUP(A4,[1]!TablaEquipos[#Data],2,FALSE),0) -> 700 | E4: =B4*C4*D4 -> 700
A5: Pica | B5: 2 | C5: 0.5 | D5: =IFERROR(VLOOKUP(A5,[1]!TablaEquipos[#Data],2,FALSE),0) -> 700 | E5: =B5*C5*D5 -> 700
A6: Barra | B6: 2 | C6: 1 | D6: =IFERROR(VLOOKUP(A6,[1]!TablaEquipos[#Data],2,FALSE),0) -> 1500 | E6: =B6*C6*D6 -> 3000
A7: Carretilla | B7: 2 | C7: 1 | D7: =IFERROR(VLOOKUP(A7,[1]!TablaEquipos[#Data],2,FALSE),0) -> 1500 | E7: =B7*C7*D7 -> 3000
D8: 45000 | E8: =B8*C8*D8 -> 0
A9: Termo agua | B9: 1 | C9: 2 | D9: 4000 | E9: =B9*C9*D9 -> 8000
A10: Botiquin primeros auxilios | B10: 1 | C10: 2 | D10: 4000 | E10: =B10*C10*D10 -> 8000
A11: Camilla primeros auxilios | B11: 1 | C11: 2 | D11: 3000 | E11: =B11*C11*D11 -> 6000
A12: Colombianas de seguridad | B12: 10 | C12: 2 | D12: 1000 | E12: =B12*C12*D12 -> 20000
A13: Avisos de seguridad | B13: 20 | C13: 2 | D13: 500 | E13: =B13*C13*D13 -> 20000
D18: =IFERROR(VLOOKUP(A18,[1]!TablaEquipos[#Data],2,FALSE),0) -> 0 | E18: =B18*C18*D18 -> 0
D19: =IFERROR(VLOOKUP(A19,[1]!TablaEquipos[#Data],2,FALSE),0) -> 0 | E19: =B19*C19*D19 -> 0
F20: =SUM(E4:E18) -> 69400
A21: MATERIALES | B21: CANT | C21: REND/DIA | D21: TARIFA | E21: VR.PARCIAL
A22: Cinta de seguridad amarilla/negra x 500 | B22: 1 | D22: =IFERROR(VLOOKUP(A22,[1]!TablaMateriales[#Data],2,FALSE),0) -> 55000 | E22: =B22*D22 -> 55000
D23: =IFERROR(VLOOKUP(A23,[1]!TablaMateriales[#Data],2,FALSE),0) -> 0
D24: =IFERROR(VLOOKUP(A24,[1]!TablaMateriales[#Data],2,FALSE),0) -> 0
D25: =IFERROR(VLOOKUP(A25,[1]!TablaMateriales[#Data],2,FALSE),0) -> 0
D26: =IFERROR(VLOOKUP(A26,[1]!TablaMateriales[#Data],2,FALSE),0) -> 0
F27: =SUM(E22:E26) -> 55000
A28: MANO DE OBRA | B28: CANT | C28: REND/DIA | D28: SALARIO | E28: VR.PARCIAL
A29: Capataz | B29: 1 | C29: 0.58 | D29: ='tabla salarial'!AS4 -> 555393.74 | E29: =B29*C29*D29 -> 322128.37
A30: Hse | B30: 1 | C30: 0.58 | D30: ='tabla salarial'!AS4 -> 555393.74 | E30: =B30*C30*D30 -> 322128.37
A31: auxiliar administracion | B31: 1 | C31: 0.58 | D31: ='tabla salarial'!AS8 -> 355821.88 | E31: =B31*C31*D31 -> 206376.69
A32: Oficial construccion | B32: 1 | C32: 1.57 | D32: ='tabla salarial'!AS7 -> 371571.33 | E32: =B32*C32*D32 -> 583366.99
A33: Auxiliar civil | B33: 1 | C33: 1.57 | D33: ='tabla salarial'!AS9 -> 382109.06 | E33: =B33*C33*D33 -> 599911.22
A34: 3 | F34: =SUM(E29:E33) -> 2033911.6
A35: TRANSPORTE | B35: CANT | C35: REND/DIA | D35: TARIFA | E35: VR.PARCIAL
A36: retro excavadora de llanta | B36: 1 | C36: 1.5 | D36: =IFERROR(VLOOKUP(A36,[1]!TablaTransporte[#Data],2,FALSE),0) -> 1330000 | E36: =B36*C36*D36 -> 1995000
A37: Volqueta de 14 m³ | B37: 1 | C37: 1.5 | D37: =IFERROR(VLOOKUP(A37,[1]!TablaTransporte[#Data],2,FALSE),0) -> 1350000 | E37: =B37*C37*D37 -> 2025000
A38: trasporte de equipos | B38: 1 | C38: 0.33 | D38: =IFERROR(VLOOKUP(A38,[1]!TablaTransporte[#Data],2,FALSE),0) -> 1650000 | E38: =B38*C38*D38 -> 544500
D39: =IFERROR(VLOOKUP(A39,[1]!TablaTransporte[#Data],2,FALSE),0) -> 0
F40: =SUM(E36:E38) -> 4564500
F41: =F20+F27+F34+F40 -> 6722811.6
F42: =F41*A42 -> 0
F43: =F41+F42 -> 6722811.6
F44: =F43*A44 -> 0
...

Sheet excavación con presencia 
A1: EXCAVACIÓN MECANICA CON PRESENCIA DE TUBERÍA O FACILIDAD ENTERRADA
A2: EQUIPOS | B2: CANT | C2: REND/DIA | D2: TARIFA/DIA | E2: VR.PARCIAL | F2: M3
F3: 820
A4: pala | B4: 4 | C4: 23.4 | D4: =IFERROR(VLOOKUP(A4,[1]!TablaEquipos[#Data],2,FALSE),0) -> 700 | E4: =B4*C4*D4 -> 65520
A5: Pica | B5: 1 | C5: 23.4 | D5: =IFERROR(VLOOKUP(A5,[1]!TablaEquipos[#Data],2,FALSE),0) -> 700 | E5: =B5*C5*D5 -> 16380
A6: Palín | B6: 4 | C6: 23.4 | D6: =IFERROR(VLOOKUP(A6,[1]!TablaEquipos[#Data],2,FALSE),0) -> 700 | E6: =B6*C6*D6 -> 65520
A7: Paladraga | B7: 1 | C7: 23.4 | D7: =IFERROR(VLOOKUP(A7,[1]!TablaEquipos[#Data],2,FALSE),0) -> 1500 | E7: =B7*C7*D7 -> 35100
A8: Barra | B8: 1 | C8: 23.4 | D8: =IFERROR(VLOOKUP(A8,[1]!TablaEquipos[#Data],2,FALSE),0) -> 1500 | E8: =B8*C8*D8 -> 35100
A9: Herramientero | B9: 1 | C9: 23.4 | D9: =IFERROR(VLOOKUP(A9,[1]!TablaEquipos[#Data],2,FALSE),0) -> 1500 | E9: =B9*C9*D9 -> 35100
A10: Sierra circular | B10: 1 | C10: 2 | D10: =IFERROR(VLOOKUP(A10,[1]!TablaEquipos[#Data],2,FALSE),0) -> 15000 | E10: =B10*C10*D10 -> 30000
A11: Carretilla | B11: 3 | C11: 23.4 | D11: =IFERROR(VLOOKUP(A11,[1]!TablaEquipos[#Data],2,FALSE),0) -> 1500 | E11: =B11*C11*D11 -> 105300
A12: Botiquin primeros auxilios | B12: 1 | C12: 23.4 | D12: =IFERROR(VLOOKUP(A12,[1]!TablaEquipos[#Data],2,FALSE),0) -> 4000 | E12: =B12*C12*D12 -> 93600
A13: Camilla primeros auxilios | B13: 1 | C13: 23.4 | D13: =IFERROR(VLOOKUP(A13,[1]!TablaEquipos[#Data],2,FALSE),0) -> 3000 | E13: =B13*C13*D13 -> 70200
A14: Thermo agua | B14: 2 | C14: 23.4 | D14: =IFERROR(VLOOKUP(A14,[1]!TablaEquipos[#Data],2,FALSE),0) -> 1750 | E14: =B14*C14*D14 -> 81900
D15: =IFERROR(VLOOKUP(A15,[1]!TablaEquipos[#Data],2,FALSE),0) -> 0 | E15: =B15*C15*D15 -> 0
F16: =SUM(E4:E15) -> 633720
A17: MATERIALES | B17: CANT | C17: REND/DIA | D17: TARIFA | E17: VR.PARCIAL
A18: Listón de madera 2 x 1 x 3 | B18: 25 | D18: =IFERROR(VLOOKUP(A18,[1]!TablaMateriales[#Data],2,FALSE),0) -> 20000 | E18: =B18*D18 -> 500000
A19: Manila 5/16" | B19: 80 | D19: 3200 | E19: =B19*D19 -> 256000
D20: =IFERROR(VLOOKUP(A20,[1]!TablaMateriales[#Data],2,FALSE),0) -> 0
D21: =IFERROR(VLOOKUP(A21,[1]!TablaMateriales[#Data],2,FALSE),0) -> 0
D22: =IFERROR(VLOOKUP(A22,[1]!TablaMateriales[#Data],2,FALSE),0) -> 0
F23: =SUM(E18:E22) -> 756000
A24: MANO DE OBRA | B24: CANT | C24: REND/DIA | D24: SALARIO | E24: VR.PARCIAL
A25: Capataz | B25: 1 | C25: 13 | D25: ='tabla salarial'!AS4 -> 555393.74 | E25: =B25*C25*D25 -> 7220118.6
A26: Hse | B26: 1 | C26: 13 | D26: ='tabla salarial'!AS4 -> 555393.74 | E26: =B26*C26*D26 -> 7220118.6
A27: Rescatista | B27: 1 | C27: 38 | D27: ='tabla salarial'!AS5 -> 443956.94 | E27: =B27*C27*D27 -> 16870364
A28: Auxiliar Administrativo | B28: 1 | C28: 13 | D28: ='tabla salarial'!AS8 -> 355821.88 | E28: =B28*C28*D28 -> 4625684.4
A29: Oficial construccion | B29: 1 | C29: 38 | D29: ='tabla salarial'!AS7 -> 371571.33 | E29: =B29*C29*D29 -> 14119711
A30: Auxiliar civil | B30: 4 | C30: 38 | D30: ='tabla salarial'!AS9 -> 382109.06 | E30: =B30*C30*D30 -> 58080577
A31: 3 | F31: =SUM(E25:E30) -> 1.0813657e+08
A32: TRANSPORTE | B32: CANT | C32: REND/DIA | D32: TARIFA | E32: VR.PARCIAL
A33: Retroexcavadora de oruga | B33: 1 | C33: 23.4 | D33: =IFERROR(VLOOKUP(A33,[1]!TablaTransporte[#Data],2,FALSE),0) -> 322000 | E33: =B33*C33*D33 -> 7534800
A34: trasporte de equipo | B34: 1 | C34: 2 | D34: =IFERROR(VLOOKUP(A34,[1]!TablaTransporte[#Data],2,FALSE),0) -> 4500000 | E34: =B34*C34*D34 -> 9000000
A35: Buseta Acpm | B35: 1 | C35: 24 | D35: =IFERROR(VLOOKUP(A35,[1]!TablaTransporte[#Data],2,FALSE),0) -> 600000 | E35: =B35*C35*D35 -> 14400000 | F35: =SUM(E33:E34) -> 16534800
F36: =F16+F23+F31+F35 -> 1.2606109e+08
F37: =F36*A37 -> 0
F38: =F36+F37 -> 1.2606109e+08
F39: =F38*A39 -> 0
F40: =F38+F39 -> 1.2606109e+08
...

Sheet demolición concreto
A1: DEMOLICIÓN CONCRETO Y/O ROCA CON MARTILLO NEUMÁTICO
A2: EQUIPOS | B2: CANT | C2: REND/DIA | D2: TARIFA/DIA | E2: VR.PARCIAL | F2: M3
F3: 52
A4: Pala | B4: 4 | C4: 32 | D4: =IFERROR(VLOOKUP(A4,[1]!TablaEquipos[#Data],2,FALSE),0) -> 700 | E4: =B4*C4*D4 -> 89600
A5: Barra | B5: 4 | C5: 32 | D5: =IFERROR(VLOOKUP(A5,[1]!TablaEquipos[#Data],2,FALSE),0) -> 1500 | E5: =B5*C5*D5 -> 192000
A6: Herramientero | B6: 1 | C6: 32 | D6: =IFERROR(VLOOKUP(A6,[1]!TablaEquipos[#Data],2,FALSE),0) -> 1500 | E6: =B6*C6*D6 -> 48000
A7: Carretilla | B7: 6 | C7: 32 | D7: =IFERROR(VLOOKUP(A7,[1]!TablaEquipos[#Data],2,FALSE),0) -> 1500 | E7: =B7*C7*D7 -> 288000
A8: Martillo demoledor neumático/eléctrico | B8: 3 | C8: 32 | D8: =IFERROR(VLOOKUP(A8,[1]!TablaEquipos[#Data],2,FALSE),0) -> 80000 | E8: =B8*C8*D8 -> 7680000
A9: Pulidora 7" | B9: 1 | C9: 32 | D9: =IFERROR(VLOOKUP(A9,[1]!TablaEquipos[#Data],2,FALSE),0) -> 15000 | E9: =B9*C9*D9 -> 480000
A10: Extencion electrica 100mts | B10: 3 | C10: 32 | D10: =IFERROR(VLOOKUP(A10,[1]!TablaEquipos[#Data],2,FALSE),0) -> 15000 | E10: =B10*C10*D10 -> 1440000
A11: Planta electrica 7,5 kwa | B11: 1 | C11: 32 | D11: =IFERROR(VLOOKUP(A11,[1]!TablaEquipos[#Data],2,FALSE),0) -> 40000 | E11: =B11*C11*D11 -> 1280000
A12: taladro Rotomartillo | B12: 1 | C12: 32 | D12: 60000 | E12: =B12*C12*D12 -> 1920000
F19: =SUM(E4:E18) -> 13417600
A20: MATERIALES | B20: CANT | C20: REND/DIA | D20: TARIFA | E20: VR.PARCIAL
A21: Cinta de seguridad amarilla/negra x 500 | B21: 1 | D21: =IFERROR(VLOOKUP(A21,[1]!TablaMateriales[#Data],2,FALSE),0) -> 55000 | E21: =B21*D21 -> 55000 | H21: 100
A22: Broca tipo pala | B22: 15 | D22: =IFERROR(VLOOKUP(A22,[1]!TablaMateriales[#Data],2,FALSE),0) -> 65000 | E22: =B22*D22 -> 975000
A23: Broca tipo punta | B23: 15 | D23: =IFERROR(VLOOKUP(A23,[1]!TablaMateriales[#Data],2,FALSE),0) -> 65000 | E23: =B23*D23 -> 975000
A24: Aceite lubricante | B24: 1 | D24: =IFERROR(VLOOKUP(A24,[1]!TablaMateriales[#Data],2,FALSE),0) -> 65000 | E24: =B24*D24 -> 65000
A25: Aceite 15w40 | B25: 1 | D25: =IFERROR(VLOOKUP(A25,[1]!TablaMateriales[#Data],2,FALSE),0) -> 85000 | E25: =B25*D25 -> 85000
A26: Broca Rotomartillo 1 1/4 x 12" | B26: 1 | D26: =IFERROR(VLOOKUP(A26,[1]!TablaMateriales[#Data],2,FALSE),0) -> 455000 | E26: =B26*D26 -> 455000
A27: Sacos de polipropileno | B27: 100 | D27: =IFERROR(VLOOKUP(A27,[1]!TablaMateriales[#Data],2,FALSE),0) -> 1200 | E27: =B27*D27 -> 120000
A28: guantes antivibración | B28: 8 | D28: =IFERROR(VLOOKUP(A28,[1]!TablaMateriales[#Data],2,FALSE),0) -> 33200 | E28: =B28*D28 -> 265600
A29: careta de esmerilar para casco | B29: 8 | D29: =IFERROR(VLOOKUP(A29,[1]!TablaMateriales[#Data],2,FALSE),0) -> 42000 | E29: =B29*D29 -> 336000
A30: Suelo o arena para sacos con transporte | B30: 7 | D30: =IFERROR(VLOOKUP(A30,[1]!TablaMateriales[#Data],2,FALSE),0) -> 58000 | E30: =B30*D30 -> 406000
A31: discos de corte de 7" / discos diamantados o abrasivos | B31: 10 | D31: =IFERROR(VLOOKUP(A31,[1]!TablaMateriales[#Data],2,FALSE),0) -> 62000 | E31: =B31*D31 -> 620000
A32: Disco de corte 7" para metarl 1 1/16" | B32: 20 | D32: =IFERROR(VLOOKUP(A32,[1]!TablaMateriales[#Data],2,FALSE),0) -> 11500 | E32: =B32*D32 -> 230000
A33: Cras | B33: 1 | D33: =IFERROR(VLOOKUP(A33,[1]!TablaMateriales[#Data],2,FALSE),0) -> 1185900 | E33: =B33*D33 -> 1185900
A34: ACPM | B34: 10 | D34: =IFERROR(VLOOKUP(A34,[1]!TablaMateriales[#Data],2,FALSE),0) -> 0 | E34: =B34*D34 -> 0
F35: =SUM(E21:E34) -> 5773500
A36: MANO DE OBRA | B36: CANT | C36: REND/DIA | D36: SALARIO | E36: VR.PARCIAL
A37: Capataz | B37: 1 | C37: 40 | D37: ='tabla salarial'!AS4 -> 555393.74 | E37: =B37*C37*D37 -> 22215750
A38: Hse | B38: 1 | C38: 40 | D38: ='tabla salarial'!AS4 -> 555393.74 | E38: =B38*C38*D38 -> 22215750
A39: Oficial construccion | B39: 2 | C39: 40 | D39: ='tabla salarial'!AS7 -> 371571.33 | E39: =B39*C39*D39 -> 29725706
A40: Auxiliar Administrativo | B40: 1 | C40: 40 | D40: ='tabla salarial'!AS8 -> 355821.88 | E40: =B40*C40*D40 -> 14232875
A41: Auxiliar civil | B41: 12 | C41: 40 | D41: ='tabla salarial'!AS9 -> 382109.06 | E41: =B41*C41*D41 -> 1.8341235e+08
F42: =SUM(E37:E41) -> 2.7180243e+08
A43: TRANSPORTE | B43: CANT | C43: REND/DIA | D43: TARIFA | E43: VR.PARCIAL
A44: Camión doble cabina | B44: 1 | C44: 1 | D44: =IFERROR(VLOOKUP(A44,[1]!TablaTransporte[#Data],2,FALSE),0) -> 550000 | E44: =B44*C44*D44 -> 550000
A45: Acarreo por km | D45: =IFERROR(VLOOKUP(A45,[1]!TablaTransporte[#Data],2,FALSE),0) -> 65000 | E45: =B45*C45*D45 -> 0
A46: Retroexcavadora de llantas | B46: 1 | C46: 1 | D46: =IFERROR(VLOOKUP(A46,[1]!TablaTransporte[#Data],2,FALSE),0) -> 1330000 | E46: =B46*C46*D46 -> 1330000
...

Sheet relleno manual 
A1: RELLENO MANUAL COMPACTADO-MATERIAL DE SITIO, PRODUCTO DE EXCAVACIÓN
A2: EQUIPOS | B2: CANT | C2: REND/DIA | D2: TARIFA/DIA | E2: VR.PARCIAL | F2: M3
F3: 780
A4: Pala | B4: 8 | C4: 35 | D4: =IFERROR(VLOOKUP(A4,[1]!TablaEquipos[#Data],2,FALSE),0) -> 700 | E4: =B4*C4*D4 -> 196000
A5: Pica | B5: 8 | C5: 35 | D5: =IFERROR(VLOOKUP(A5,[1]!TablaEquipos[#Data],2,FALSE),0) -> 700 | E5: =B5*C5*D5 -> 196000
A6: Palín | B6: 8 | C6: 35 | D6: =IFERROR(VLOOKUP(A6,[1]!TablaEquipos[#Data],2,FALSE),0) -> 700 | E6: =B6*C6*D6 -> 196000
A7: Barra | B7: 2 | C7: 35 | D7: =IFERROR(VLOOKUP(A7,[1]!TablaEquipos[#Data],2,FALSE),0) -> 1500 | E7: =B7*C7*D7 -> 105000
A8: Herramientero | B8: 1 | C8: 35 | D8: =IFERROR(VLOOKUP(A8,[1]!TablaEquipos[#Data],2,FALSE),0) -> 1500 | E8: =B8*C8*D8 -> 52500
A9: Sierra circular | B9: 1 | D9: =IFERROR(VLOOKUP(A9,[1]!TablaEquipos[#Data],2,FALSE),0) -> 15000 | E9: =B9*C9*D9 -> 0
A10: Carretilla | B10: 6 | C10: 35 | D10: =IFERROR(VLOOKUP(A10,[1]!TablaEquipos[#Data],2,FALSE),0) -> 1500 | E10: =B10*C10*D10 -> 315000
A11: Vibrocompactador tipo rana | B11: 1 | C11: 20 | D11: =IFERROR(VLOOKUP(A11,[1]!TablaEquipos[#Data],2,FALSE),0) -> 40000 | E11: =B11*C11*D11 -> 800000
A12: Vibrocompactador tipo canguro | B12: 1 | C12: 15 | D12: =IFERROR(VLOOKUP(A12,[1]!TablaEquipos[#Data],2,FALSE),0) -> 60000 | E12: =B12*C12*D12 -> 900000
A13: Pizon manual | B13: 4 | C13: 35 | D13: =IFERROR(VLOOKUP(A13,[1]!TablaEquipos[#Data],2,FALSE),0) -> 1000 | E13: =B13*C13*D13 -> 140000
D14: =IFERROR(VLOOKUP(A14,[1]!TablaEquipos[#Data],2,FALSE),0) -> 0 | E14: =B14*C14*D14 -> 0
D15: 0 | E15: =B15*C15*D15 -> 0
F16: =SUM(E4:E15) -> 2900500
A17: MATERIALES | B17: CANT | C17: REND/DIA | D17: TARIFA | E17: VR.PARCIAL
A18: Plástico negro | B18: 100 | D18: =IFERROR(VLOOKUP(A18,[1]!TablaMateriales[#Data],2,FALSE),0) -> 9500 | E18: =B18*D18 -> 950000
A19: Acpm galon | B19: 15 | D19: =IFERROR(VLOOKUP(A19,[1]!TablaMateriales[#Data],2,FALSE),0) -> 11500 | E19: =B19*D19 -> 172500
A20: Agua m3 | B20: 40 | C20: 1 | D20: =IFERROR(VLOOKUP(A20,[1]!TablaMateriales[#Data],2,FALSE),0) -> 6000 | E20: =B20*D20 -> 240000
F23: =SUM(E18:E22) -> 1362500
A24: MANO DE OBRA | B24: CANT | C24: REND/DIA | D24: SALARIO | E24: VR.PARCIAL
A25: Capataz | B25: 1 | C25: 44 | D25: 539456.24 | E25: =B25*C25*D25 -> 23736075
A26: Hse | B26: 1 | C26: 44 | D26: 539456.24 | E26: =B26*C26*D26 -> 23736075
A27: Topografo | D27: 539456.24 | E27: =B27*C27*D27 -> 0
A28: Cadenero 1 | D28: 434781.14 | E28: =B28*C28*D28 -> 0
A29: Andamiero | D29: 434781.14 | E29: =B29*C29*D29 -> 0
A30: Oficial construccion | B30: 2 | C30: 44 | D30: 399154.66 | E30: =B30*C30*D30 -> 35125610
A31: Auxiliar Administrativo | B31: 1 | C31: 44 | D31: 383405.21 | E31: =B31*C31*D31 -> 16869829
A32: Auxiliar civil | B32: 8 | C32: 44 | D32: 355463.25 | E32: =B32*C32*D32 -> 1.2512306e+08
F33: =SUM(E25:E32) -> 2.2459065e+08
A34: TRANSPORTE | B34: CANT | C34: REND/DIA | D34: TARIFA | E34: VR.PARCIAL
A35: Camión doble cabina viaje | B35: 1 | C35: 10 | D35: =IFERROR(VLOOKUP(A35,[1]!TablaTransporte[#Data],2,FALSE),0) -> 0 | E35: =B35*C35*D35 -> 0
A36: Buseta | B36: 1 | C36: 28 | D36: =IFERROR(VLOOKUP(A36,[1]!TablaTransporte[#Data],2,FALSE),0) -> 0 | E36: =B36*C36*D36 -> 0
D37: =IFERROR(VLOOKUP(A37,[1]!TablaTransporte[#Data],2,FALSE),0) -> 0
F39: =SUM(E35:E36) -> 0
F40: =F16+F23+F33+F39 -> 2.2885365e+08
F41: =F40*A41 -> 0
F42: =F40+F41 -> 2.2885365e+08
F43: =F42*A43 -> 0
...

Sheet relleno mecanico
A1: RELLENO MECÁNICO COMPACTADO CON MATERIAL DE SITIO
A2: EQUIPOS | B2: CANT | C2: REND/DIA | D2: TARIFA/DIA | E2: VR.PARCIAL | F2: M3
F3: 269
A4: Machete | D4: =IFERROR(VLOOKUP(A4,[1]!TablaEquipos[#Data],2,FALSE),0) -> 1500 | E4: =B4*C4*D4 -> 0 | F4: =SUM(E4:E25) -> 1186750
A5: Martillo | D5: =IFERROR(VLOOKUP(A5,[1]!TablaEquipos[#Data],2,FALSE),0) -> 700 | E5: =B5*C5*D5 -> 0
A6: Pala | B6: 3 | C6: 15 | D6: =IFERROR(VLOOKUP(A6,[1]!TablaEquipos[#Data],2,FALSE),0) -> 700 | E6: =B6*C6*D6 -> 31500
A7: Pica | D7: =IFERROR(VLOOKUP(A7,[1]!TablaEquipos[#Data],2,FALSE),0) -> 700 | E7: =B7*C7*D7 -> 0
A8: Palín | B8: 3 | C8: 15 | D8: =IFERROR(VLOOKUP(A8,[1]!TablaEquipos[#Data],2,FALSE),0) -> 700 | E8: =B8*C8*D8 -> 31500
A9: Paladraga | D9: =IFERROR(VLOOKUP(A9,[1]!TablaEquipos[#Data],2,FALSE),0) -> 1500 | E9: =B9*C9*D9 -> 0
A10: Barra | B10: 1 | C10: 15 | D10: =IFERROR(VLOOKUP(A10,[1]!TablaEquipos[#Data],2,FALSE),0) -> 1500 | E10: =B10*C10*D10 -> 22500
A11: Herramientero | B11: 1 | C11: 15 | D11: =IFERROR(VLOOKUP(A11,[1]!TablaEquipos[#Data],2,FALSE),0) -> 1500 | E11: =B11*C11*D11 -> 22500
A12: Sierra circular | D12: =IFERROR(VLOOKUP(A12,[1]!TablaEquipos[#Data],2,FALSE),0) -> 15000 | E12: =B12*C12*D12 -> 0
A13: Alicate diablo | D13: =IFERROR(VLOOKUP(A13,[1]!TablaEquipos[#Data],2,FALSE),0) -> 500 | E13: =B13*C13*D13 -> 0
A14: Alicate universal | D14: =IFERROR(VLOOKUP(A14,[1]!TablaEquipos[#Data],2,FALSE),0) -> 500 | E14: =B14*C14*D14 -> 0
